<?xml version="1.0" ?>
<robot name="my_robot">

  <link name="base_footprint"/>

  <joint name="base_joint" type="fixed">
    <parent link="base_footprint"/>
    <child link="base_link"/>
    <origin xyz="0 0 0.010" rpy="0 0 0"/>
  </joint>

  <link name="base_link">
    <visual>
      <origin xyz="-0.064 0 0.047" rpy="0 0 0"/>
      <geometry>
        <box size="0.266 0.266 0.094"/>
      </geometry>
      <material name="dark_grey">
        <color rgba="0.3 0.3 0.3 1.0"/>
      </material>
    </visual>
    <collision>
      <origin xyz="-0.064 0 0.047" rpy="0 0 0"/>
      <geometry>
        <box size="0.266 0.266 0.094"/>
      </geometry>
    </collision>
    <inertial>
      <origin xyz="-0.064 0 0.047" rpy="0 0 0"/>
      <mass value="1.372"/>
      <inertia ixx="0.00873" ixy="0.0" ixz="0.0" iyy="0.01019" iyz="0.0" izz="0.01145"/>
    </inertial>
  </link>

  <joint name="wheel_left_joint" type="continuous">
    <parent link="base_link"/>
    <child link="wheel_left_link"/>
    <origin xyz="0.0 0.144 0.023" rpy="-1.570796 0 0"/>
    <axis xyz="0 0 1"/>
  </joint>

  <link name="wheel_left_link">
    <visual>
      <origin xyz="0 0 0" rpy="0 0 0"/>
      <geometry>
        <cylinder length="0.018" radius="0.033"/>
      </geometry>
    </visual>
    <collision>
      <origin xyz="0 0 0" rpy="0 0 0"/>
      <geometry>
        <cylinder length="0.018" radius="0.033"/>
      </geometry>
    </collision>
    <inertial>
      <origin xyz="0 0 0"/>
      <mass value="0.028"/>
      <inertia ixx="1.117e-05" ixy="0.0" ixz="0.0" iyy="1.119e-05" iyz="0.0" izz="2.071e-05"/>
    </inertial>
  </link>

  <joint name="wheel_right_joint" type="continuous">
    <parent link="base_link"/>
    <child link="wheel_right_link"/>
    <origin xyz="0.0 -0.144 0.023" rpy="-1.570796 0 0"/>
    <axis xyz="0 0 1"/>
  </joint>

  <link name="wheel_right_link">
    <visual>
      <origin xyz="0 0 0" rpy="0 0 0"/>
      <geometry>
        <cylinder length="0.018" radius="0.033"/>
      </geometry>
    </visual>
    <collision>
      <origin xyz="0 0 0" rpy="0 0 0"/>
      <geometry>
        <cylinder length="0.018" radius="0.033"/>
      </geometry>
    </collision>
    <inertial>
      <origin xyz="0 0 0"/>
      <mass value="0.028"/>
      <inertia ixx="1.117e-05" ixy="0.0" ixz="0.0" iyy="1.119e-05" iyz="0.0" izz="2.071e-05"/>
    </inertial>
  </link>
  <joint name="imu_joint" type="fixed">
    <parent link="base_link"/>
    <child link="imu_link"/>
    <origin xyz="0.0 0.0 0.0" rpy="0 0 0"/>
  </joint>
  <joint name="lidar_joint" type="fixed">
    <parent link="base_link"/>
    <child link="base_scan"/>
    <origin xyz="-0.064 0 0.122" rpy="0 0 0"/>
  </joint>

  <link name="imu_link"/>

  <link name="base_scan">
    <visual>
      <origin xyz="0 0 0" rpy="0 0 0"/>
      <geometry>
        <cylinder length="0.0315" radius="0.055"/>
      </geometry>
    </visual>
    <collision>
      <origin xyz="0 0 0" rpy="0 0 0"/>
      <geometry>
        <cylinder length="0.0315" radius="0.055"/>
      </geometry>
    </collision>
    <inertial>
      <mass value="0.114"/>
      <origin xyz="0 0 0"/>
      <inertia ixx="0.001" ixy="0.0" ixz="0.0" iyy="0.001" iyz="0.0" izz="0.001"/>
    </inertial>
  </link>

  <gazebo>
    <plugin name="my_robot_diff_drive" filename="libgazebo_ros_diff_drive.so">
      <ros>
        <remapping>odom:=odom</remapping>
        <namespace>/</namespace>
      </ros>
      <update_rate>30</update_rate>
      <left_joint>wheel_left_joint</left_joint>
      <right_joint>wheel_right_joint</right_joint>
      <wheel_separation>0.287</wheel_separation>
      <wheel_diameter>0.066</wheel_diameter>
      <max_wheel_torque>20</max_wheel_torque>
      <max_wheel_acceleration>1.0</max_wheel_acceleration>
      <command_topic>cmd_vel</command_topic>
      <publish_odom>true</publish_odom>
      <publish_odom_tf>true</publish_odom_tf>
      <publish_wheel_tf>false</publish_wheel_tf>
      <odometry_topic>odom</odometry_topic>
      <odometry_frame>odom</odometry_frame>
      <robot_base_frame>base_footprint</robot_base_frame>
    </plugin>
  </gazebo>

  <gazebo reference="base_scan">
    <sensor name="my_robot_lds" type="ray">
      <always_on>true</always_on>
      <visualize>true</visualize>
      <update_rate>5</update_rate>
      <ray>
        <scan>
          <horizontal>
            <samples>360</samples>
            <resolution>1</resolution>
            <min_angle>0.0</min_angle>
            <max_angle>6.28319</max_angle>
          </horizontal>
        </scan>
        <range>
          <min>0.120</min>
          <max>3.5</max>
          <resolution>0.015</resolution>
        </range>
      </ray>
      <plugin name="my_robot_laserscan" filename="libgazebo_ros_ray_sensor.so">
        <ros>
          <namespace>/</namespace>
          <remapping>~/out:=/scan</remapping>
        </ros>
        <output_type>sensor_msgs/LaserScan</output_type>
        <frame_name>base_scan</frame_name>
      </plugin>
    </sensor>
  </gazebo>
<link name="camera_link">
    <visual>
      <geometry>
        <box size="0.05 0.05 0.05"/>
      </geometry>
      <material name="blue"/>
    </visual>
    <inertial>
      <mass value="0.001"/>
      <inertia ixx="1e-6" ixy="0" ixz="0" iyy="1e-6" iyz="0" izz="1e-6"/>
    </inertial>
    <collision>
      <geometry><box size="0.01 0.01 0.01"/></geometry>
    </collision>
  </link>

  <joint name="camera_joint" type="fixed">
    <parent link="base_link"/>
    <child link="camera_link"/>
    <origin xyz="0.1 0.0 0.2" rpy="0 0 0"/> 
  </joint>

  <gazebo reference="camera_link">
    <material>Gazebo/Blue</material>
    <sensor type="camera" name="robot_camera">
      <update_rate>30</update_rate>
      <visualize>false</visualize>
      <camera>
        <horizontal_fov>1.3962634</horizontal_fov>
        <image>
          <width>640</width>
          <height>480</height>
          <format>R8G8B8</format>
        </image>
        <clip>
          <near>0.02</near>
          <far>300</far>
        </clip>
      </camera>
      <plugin name="camera_controller" filename="libgazebo_ros_camera.so">
        <ros>
          <namespace>myrobot</namespace>
          <remapping>robot_camera/image_raw:=camera/image_raw</remapping>
          <remapping>robot_camera/camera_info:=camera/camera_info</remapping>
        </ros>
        <frame_name>camera_link</frame_name>
      </plugin>
    </sensor>
  </gazebo>

  <link name="depth_camera_link">
    <visual>
      <geometry><box size="0.04 0.04 0.04"/></geometry>
    </visual>
    <inertial>
      <mass value="0.001"/>
      <inertia ixx="1e-6" ixy="0" ixz="0" iyy="1e-6" iyz="0" izz="1e-6"/>
    </inertial>
    <collision>
      <geometry><box size="0.01 0.01 0.01"/></geometry>
    </collision>
  </link>

  <joint name="depth_camera_joint" type="fixed">
    <parent link="base_link"/>
    <child link="depth_camera_link"/>
    <origin xyz="0.1 0.0 0.2" rpy="0 0 0"/>
  </joint>

  <gazebo reference="depth_camera_link">
    <sensor type="depth" name="depth_camera">
      <update_rate>10</update_rate>
      <visualize>false</visualize>
      <camera>
        <horizontal_fov>1.3962634</horizontal_fov>
        <image>
          <width>640</width>
          <height>480</height>
          <format>R8G8B8</format>
        </image>
        <depth_camera></depth_camera>
        <clip>
          <near>0.05</near>
          <far>10.0</far>
        </clip>
      </camera>
      <plugin name="depth_camera_controller" filename="libgazebo_ros_camera.so">
        <ros>
          <namespace>camera</namespace>
          <remapping>depth_camera/image_raw:=depth/image_raw</remapping>
          <remapping>depth_camera/camera_info:=depth/camera_info</remapping>
          <remapping>depth_camera/points:=depth/points</remapping>
        </ros>
        <frame_name>depth_camera_link</frame_name>
        <min_depth>0.05</min_depth>
        <max_depth>10.0</max_depth>
      </plugin>
    </sensor>
  </gazebo>
</robot>
